
INFO     : 2022-07-16 10:51:52,995 : [server.py : 253] : Shutting down
INFO     : 2022-07-16 10:51:53,105 : [on.py : 66] : Waiting for application shutdown.
INFO     : 2022-07-16 10:51:53,105 : [on.py : 77] : Application shutdown complete.
INFO     : 2022-07-16 10:51:53,105 : [server.py : 85] : Finished server process [8812]
INFO     : 2022-07-16 11:50:06,514 : [server.py : 75] : Started server process [3672]
INFO     : 2022-07-16 11:50:06,514 : [on.py : 47] : Waiting for application startup.
INFO     : 2022-07-16 11:50:06,514 : [on.py : 61] : Application startup complete.
INFO     : 2022-07-16 11:50:06,514 : [server.py : 207] : Uvicorn running on http://127.0.0.1:8000 (Press CTRL+C to quit)
INFO     : 2022-07-16 11:50:19,127 : [health_check.py : 15] : Request: GET localhost:8000/healthcheck
INFO     : 2022-07-16 11:50:19,127 : [health_check.py : 16] : Response: Server is Up and Running
INFO     : 2022-07-16 12:35:55,061 : [server.py : 253] : Shutting down
INFO     : 2022-07-16 12:35:55,170 : [on.py : 66] : Waiting for application shutdown.
INFO     : 2022-07-16 12:35:55,170 : [on.py : 77] : Application shutdown complete.
INFO     : 2022-07-16 12:35:55,170 : [server.py : 85] : Finished server process [3672]
INFO     : 2022-07-16 12:40:03,149 : [server.py : 75] : Started server process [7548]
INFO     : 2022-07-16 12:40:03,149 : [on.py : 47] : Waiting for application startup.
INFO     : 2022-07-16 12:40:03,149 : [on.py : 61] : Application startup complete.
INFO     : 2022-07-16 12:40:03,149 : [server.py : 207] : Uvicorn running on http://127.0.0.1:8000 (Press CTRL+C to quit)
ERROR    : 2022-07-16 12:40:45,118 : [h11_impl.py : 406] : Exception in ASGI application
Traceback (most recent call last):
  File "D:\py\pycharmProjects\api\venv\lib\site-packages\uvicorn\protocols\http\h11_impl.py", line 403, in run_asgi
    result = await app(self.scope, self.receive, self.send)
  File "D:\py\pycharmProjects\api\venv\lib\site-packages\uvicorn\middleware\proxy_headers.py", line 78, in __call__
    return await self.app(scope, receive, send)
  File "C:\Users\BEL\AppData\Roaming\Python\Python39\site-packages\fastapi\applications.py", line 269, in __call__
    await super().__call__(scope, receive, send)
  File "C:\Users\BEL\AppData\Roaming\Python\Python39\site-packages\starlette\applications.py", line 124, in __call__
    await self.middleware_stack(scope, receive, send)
  File "C:\Users\BEL\AppData\Roaming\Python\Python39\site-packages\starlette\middleware\errors.py", line 184, in __call__
    raise exc
  File "C:\Users\BEL\AppData\Roaming\Python\Python39\site-packages\starlette\middleware\errors.py", line 162, in __call__
    await self.app(scope, receive, _send)
  File "C:\Users\BEL\AppData\Roaming\Python\Python39\site-packages\starlette\exceptions.py", line 93, in __call__
    raise exc
  File "C:\Users\BEL\AppData\Roaming\Python\Python39\site-packages\starlette\exceptions.py", line 82, in __call__
    await self.app(scope, receive, sender)
  File "C:\Users\BEL\AppData\Roaming\Python\Python39\site-packages\fastapi\middleware\asyncexitstack.py", line 21, in __call__
    raise e
  File "C:\Users\BEL\AppData\Roaming\Python\Python39\site-packages\fastapi\middleware\asyncexitstack.py", line 18, in __call__
    await self.app(scope, receive, send)
  File "C:\Users\BEL\AppData\Roaming\Python\Python39\site-packages\starlette\routing.py", line 670, in __call__
    await route.handle(scope, receive, send)
  File "C:\Users\BEL\AppData\Roaming\Python\Python39\site-packages\starlette\routing.py", line 266, in handle
    await self.app(scope, receive, send)
  File "C:\Users\BEL\AppData\Roaming\Python\Python39\site-packages\starlette\routing.py", line 65, in app
    response = await func(request)
  File "C:\Users\BEL\AppData\Roaming\Python\Python39\site-packages\fastapi\routing.py", line 227, in app
    raw_response = await run_endpoint_function(
  File "C:\Users\BEL\AppData\Roaming\Python\Python39\site-packages\fastapi\routing.py", line 162, in run_endpoint_function
    return await run_in_threadpool(dependant.call, **values)
  File "C:\Users\BEL\AppData\Roaming\Python\Python39\site-packages\starlette\concurrency.py", line 41, in run_in_threadpool
    return await anyio.to_thread.run_sync(func, *args)
  File "D:\py\pycharmProjects\api\venv\lib\site-packages\anyio\to_thread.py", line 31, in run_sync
    return await get_asynclib().run_sync_in_worker_thread(
  File "D:\py\pycharmProjects\api\venv\lib\site-packages\anyio\_backends\_asyncio.py", line 937, in run_sync_in_worker_thread
    return await future
  File "D:\py\pycharmProjects\api\venv\lib\site-packages\anyio\_backends\_asyncio.py", line 867, in run
    result = context.run(func, *args)
  File "D:\py\pycharmProjects\api\api_practice\routers\health_check.py", line 26, in create_user
    new_user = UserModel(name=request.user_name, email_id=request.email_id, password=request.password)
  File "<string>", line 4, in __init__
  File "D:\py\pycharmProjects\api\venv\lib\site-packages\sqlalchemy\orm\state.py", line 482, in _initialize_instance
    manager.dispatch.init_failure(self, args, kwargs)
  File "D:\py\pycharmProjects\api\venv\lib\site-packages\sqlalchemy\util\langhelpers.py", line 70, in __exit__
    compat.raise_(
  File "D:\py\pycharmProjects\api\venv\lib\site-packages\sqlalchemy\util\compat.py", line 208, in raise_
    raise exception
  File "D:\py\pycharmProjects\api\venv\lib\site-packages\sqlalchemy\orm\state.py", line 479, in _initialize_instance
    return manager.original_init(*mixed[1:], **kwargs)
  File "D:\py\pycharmProjects\api\venv\lib\site-packages\sqlalchemy\orm\decl_base.py", line 1163, in _declarative_constructor
    raise TypeError(
TypeError: 'email_id' is an invalid keyword argument for UserModel
INFO     : 2022-07-16 12:41:40,790 : [server.py : 253] : Shutting down
INFO     : 2022-07-16 12:41:40,899 : [on.py : 66] : Waiting for application shutdown.
INFO     : 2022-07-16 12:41:40,899 : [on.py : 77] : Application shutdown complete.
INFO     : 2022-07-16 12:41:40,899 : [server.py : 85] : Finished server process [7548]
INFO     : 2022-07-16 12:41:42,133 : [server.py : 75] : Started server process [12716]
INFO     : 2022-07-16 12:41:42,133 : [on.py : 47] : Waiting for application startup.
INFO     : 2022-07-16 12:41:42,133 : [on.py : 61] : Application startup complete.
INFO     : 2022-07-16 12:41:42,133 : [server.py : 207] : Uvicorn running on http://127.0.0.1:8000 (Press CTRL+C to quit)
ERROR    : 2022-07-16 12:42:02,879 : [h11_impl.py : 406] : Exception in ASGI application
Traceback (most recent call last):
  File "D:\py\pycharmProjects\api\venv\lib\site-packages\sqlalchemy\engine\base.py", line 1819, in _execute_context
    self.dialect.do_execute(
  File "D:\py\pycharmProjects\api\venv\lib\site-packages\sqlalchemy\engine\default.py", line 732, in do_execute
    cursor.execute(statement, parameters)
sqlite3.OperationalError: table users has no column named user_name

The above exception was the direct cause of the following exception:

Traceback (most recent call last):
  File "D:\py\pycharmProjects\api\venv\lib\site-packages\uvicorn\protocols\http\h11_impl.py", line 403, in run_asgi
    result = await app(self.scope, self.receive, self.send)
  File "D:\py\pycharmProjects\api\venv\lib\site-packages\uvicorn\middleware\proxy_headers.py", line 78, in __call__
    return await self.app(scope, receive, send)
  File "C:\Users\BEL\AppData\Roaming\Python\Python39\site-packages\fastapi\applications.py", line 269, in __call__
    await super().__call__(scope, receive, send)
  File "C:\Users\BEL\AppData\Roaming\Python\Python39\site-packages\starlette\applications.py", line 124, in __call__
    await self.middleware_stack(scope, receive, send)
  File "C:\Users\BEL\AppData\Roaming\Python\Python39\site-packages\starlette\middleware\errors.py", line 184, in __call__
    raise exc
  File "C:\Users\BEL\AppData\Roaming\Python\Python39\site-packages\starlette\middleware\errors.py", line 162, in __call__
    await self.app(scope, receive, _send)
  File "C:\Users\BEL\AppData\Roaming\Python\Python39\site-packages\starlette\exceptions.py", line 93, in __call__
    raise exc
  File "C:\Users\BEL\AppData\Roaming\Python\Python39\site-packages\starlette\exceptions.py", line 82, in __call__
    await self.app(scope, receive, sender)
  File "C:\Users\BEL\AppData\Roaming\Python\Python39\site-packages\fastapi\middleware\asyncexitstack.py", line 21, in __call__
    raise e
  File "C:\Users\BEL\AppData\Roaming\Python\Python39\site-packages\fastapi\middleware\asyncexitstack.py", line 18, in __call__
    await self.app(scope, receive, send)
  File "C:\Users\BEL\AppData\Roaming\Python\Python39\site-packages\starlette\routing.py", line 670, in __call__
    await route.handle(scope, receive, send)
  File "C:\Users\BEL\AppData\Roaming\Python\Python39\site-packages\starlette\routing.py", line 266, in handle
    await self.app(scope, receive, send)
  File "C:\Users\BEL\AppData\Roaming\Python\Python39\site-packages\starlette\routing.py", line 65, in app
    response = await func(request)
  File "C:\Users\BEL\AppData\Roaming\Python\Python39\site-packages\fastapi\routing.py", line 227, in app
    raw_response = await run_endpoint_function(
  File "C:\Users\BEL\AppData\Roaming\Python\Python39\site-packages\fastapi\routing.py", line 162, in run_endpoint_function
    return await run_in_threadpool(dependant.call, **values)
  File "C:\Users\BEL\AppData\Roaming\Python\Python39\site-packages\starlette\concurrency.py", line 41, in run_in_threadpool
    return await anyio.to_thread.run_sync(func, *args)
  File "D:\py\pycharmProjects\api\venv\lib\site-packages\anyio\to_thread.py", line 31, in run_sync
    return await get_asynclib().run_sync_in_worker_thread(
  File "D:\py\pycharmProjects\api\venv\lib\site-packages\anyio\_backends\_asyncio.py", line 937, in run_sync_in_worker_thread
    return await future
  File "D:\py\pycharmProjects\api\venv\lib\site-packages\anyio\_backends\_asyncio.py", line 867, in run
    result = context.run(func, *args)
  File "D:\py\pycharmProjects\api\api_practice\routers\health_check.py", line 28, in create_user
    db.commit()
  File "D:\py\pycharmProjects\api\venv\lib\site-packages\sqlalchemy\orm\session.py", line 1451, in commit
    self._transaction.commit(_to_root=self.future)
  File "D:\py\pycharmProjects\api\venv\lib\site-packages\sqlalchemy\orm\session.py", line 829, in commit
    self._prepare_impl()
  File "D:\py\pycharmProjects\api\venv\lib\site-packages\sqlalchemy\orm\session.py", line 808, in _prepare_impl
    self.session.flush()
  File "D:\py\pycharmProjects\api\venv\lib\site-packages\sqlalchemy\orm\session.py", line 3383, in flush
    self._flush(objects)
  File "D:\py\pycharmProjects\api\venv\lib\site-packages\sqlalchemy\orm\session.py", line 3523, in _flush
    transaction.rollback(_capture_exception=True)
  File "D:\py\pycharmProjects\api\venv\lib\site-packages\sqlalchemy\util\langhelpers.py", line 70, in __exit__
    compat.raise_(
  File "D:\py\pycharmProjects\api\venv\lib\site-packages\sqlalchemy\util\compat.py", line 208, in raise_
    raise exception
  File "D:\py\pycharmProjects\api\venv\lib\site-packages\sqlalchemy\orm\session.py", line 3483, in _flush
    flush_context.execute()
  File "D:\py\pycharmProjects\api\venv\lib\site-packages\sqlalchemy\orm\unitofwork.py", line 456, in execute
    rec.execute(self)
  File "D:\py\pycharmProjects\api\venv\lib\site-packages\sqlalchemy\orm\unitofwork.py", line 630, in execute
    util.preloaded.orm_persistence.save_obj(
  File "D:\py\pycharmProjects\api\venv\lib\site-packages\sqlalchemy\orm\persistence.py", line 245, in save_obj
    _emit_insert_statements(
  File "D:\py\pycharmProjects\api\venv\lib\site-packages\sqlalchemy\orm\persistence.py", line 1238, in _emit_insert_statements
    result = connection._execute_20(
  File "D:\py\pycharmProjects\api\venv\lib\site-packages\sqlalchemy\engine\base.py", line 1631, in _execute_20
    return meth(self, args_10style, kwargs_10style, execution_options)
  File "D:\py\pycharmProjects\api\venv\lib\site-packages\sqlalchemy\sql\elements.py", line 332, in _execute_on_connection
    return connection._execute_clauseelement(
  File "D:\py\pycharmProjects\api\venv\lib\site-packages\sqlalchemy\engine\base.py", line 1498, in _execute_clauseelement
    ret = self._execute_context(
  File "D:\py\pycharmProjects\api\venv\lib\site-packages\sqlalchemy\engine\base.py", line 1862, in _execute_context
    self._handle_dbapi_exception(
  File "D:\py\pycharmProjects\api\venv\lib\site-packages\sqlalchemy\engine\base.py", line 2043, in _handle_dbapi_exception
    util.raise_(
  File "D:\py\pycharmProjects\api\venv\lib\site-packages\sqlalchemy\util\compat.py", line 208, in raise_
    raise exception
  File "D:\py\pycharmProjects\api\venv\lib\site-packages\sqlalchemy\engine\base.py", line 1819, in _execute_context
    self.dialect.do_execute(
  File "D:\py\pycharmProjects\api\venv\lib\site-packages\sqlalchemy\engine\default.py", line 732, in do_execute
    cursor.execute(statement, parameters)
sqlalchemy.exc.OperationalError: (sqlite3.OperationalError) table users has no column named user_name
[SQL: INSERT INTO users (user_name, email_id, password) VALUES (?, ?, ?)]
[parameters: ('chandru', 'chandru@mail.com', 'password')]
(Background on this error at: https://sqlalche.me/e/14/e3q8)
INFO     : 2022-07-16 12:48:08,632 : [server.py : 253] : Shutting down
INFO     : 2022-07-16 12:48:08,741 : [on.py : 66] : Waiting for application shutdown.
INFO     : 2022-07-16 12:48:08,741 : [on.py : 77] : Application shutdown complete.
INFO     : 2022-07-16 12:48:08,741 : [server.py : 85] : Finished server process [12716]
INFO     : 2022-07-16 12:48:35,912 : [server.py : 75] : Started server process [6392]
INFO     : 2022-07-16 12:48:35,912 : [on.py : 47] : Waiting for application startup.
INFO     : 2022-07-16 12:48:35,912 : [on.py : 61] : Application startup complete.
INFO     : 2022-07-16 12:48:35,912 : [server.py : 207] : Uvicorn running on http://127.0.0.1:8000 (Press CTRL+C to quit)
INFO     : 2022-07-16 12:59:03,143 : [server.py : 253] : Shutting down
INFO     : 2022-07-16 12:59:03,252 : [on.py : 66] : Waiting for application shutdown.
INFO     : 2022-07-16 12:59:03,252 : [on.py : 77] : Application shutdown complete.
INFO     : 2022-07-16 12:59:03,252 : [server.py : 85] : Finished server process [6392]
INFO     : 2022-07-16 12:59:04,408 : [server.py : 75] : Started server process [11212]
INFO     : 2022-07-16 12:59:04,408 : [on.py : 47] : Waiting for application startup.
INFO     : 2022-07-16 12:59:04,408 : [on.py : 61] : Application startup complete.
INFO     : 2022-07-16 12:59:04,408 : [server.py : 207] : Uvicorn running on http://127.0.0.1:8000 (Press CTRL+C to quit)
INFO     : 2022-07-16 13:02:47,859 : [server.py : 253] : Shutting down
INFO     : 2022-07-16 13:02:47,968 : [on.py : 66] : Waiting for application shutdown.
INFO     : 2022-07-16 13:02:47,969 : [on.py : 77] : Application shutdown complete.
INFO     : 2022-07-16 13:02:47,969 : [server.py : 85] : Finished server process [11212]
